<?xml version="1.0" ?>
<!-- =================================================================================== -->
<!-- |    This document was autogenerated by xacro from robot.xacro                    | -->
<!-- |    EDITING THIS FILE BY HAND IS NOT RECOMMENDED                                 | -->
<!-- =================================================================================== -->
<robot name="insert_robot_name_here" xmlns:xacro="http://www.ros.org/wiki/xacro">
  <link name="base">
    <visual>
      <geometry>
        <box size="0.94 0.78 1.98"/>
      </geometry>
    </visual>
  </link>
  <link name="laser_vert_bottom">
    <visual>
      <geometry>
        <box size="0.062 0.062 0.087"/>
      </geometry>
      <origin rpy="3.1355 -1.3045 0.0025" xyz="0.3158 -0.0021 0.5100"/>
    </visual>
  </link>
  <joint name="base_to_laser_vert_bottom" type="fixed">
    <parent link="base"/>
    <child link="laser_vert_bottom"/>
  </joint>
  <link name="laser_vert_top_right">
    <visual>
      <geometry>
        <box size="0.062 0.062 0.087"/>
      </geometry>
    </visual>
  </link>
  <joint name="base_to_laser_vert_top_right" type="fixed">
    <parent link="base"/>
    <child link="laser_vert_top_right"/>
    <origin rpy="-1.1760 0.6313 -1.9377" xyz="0.2978 -0.1450 1.8451"/>
  </joint>
  <link name="laser_vert_top_left">
    <visual>
      <geometry>
        <box size="0.062 0.062 0.087"/>
      </geometry>
      <origin rpy="1.1780 0.6198 1.9560" xyz="0.2997 0.1531 1.8443"/>
    </visual>
  </link>
  <joint name="base_to_laser_vert_top_left" type="fixed">
    <parent link="base"/>
    <child link="laser_vert_top_left"/>
  </joint>
  <link name="laser_horiz">
    <visual>
      <geometry>
        <cylinder length="0.072" radius="0.052"/>
      </geometry>
      <origin rpy="-0.0012 0.1146 -0.0015" xyz="0.2325 0.0001 1.9201"/>
    </visual>
  </link>
  <joint name="base_to_laser_horiz" type="fixed">
    <parent link="base"/>
    <child link="laser_horiz"/>
  </joint>
  <link name="wheel_left">
    <visual>
      <geometry>
        <cylinder length="0.05" radius="0.2"/>
      </geometry>
      <origin rpy="-1.57079632679 0.0 0.0" xyz="0.1 -0.4 0.0"/>
    </visual>
  </link>
  <joint name="base_to_wheel_left" type="continuous">
    <parent link="base"/>
    <child link="wheel_left"/>
    <limit effort="1" velocity="1"/>
  </joint>
  <link name="wheel_right">
    <visual>
      <geometry>
        <cylinder length="0.05" radius="0.2"/>
      </geometry>
      <origin rpy="-1.57079632679 0.0 0.0" xyz="0.1 0.4 0.0"/>
    </visual>
  </link>
  <joint name="base_to_wheel_right" type="continuous">
    <parent link="base"/>
    <child link="wheel_right"/>
    <limit effort="1" velocity="1"/>
  </joint>
  <link name="wheel_center">
    <visual>
      <geometry>
        <cylinder length="0.05" radius="0.15"/>
      </geometry>
      <origin rpy="-1.57079632679 0.0 0.0" xyz="0.1 0.0 0.0"/>
    </visual>
  </link>
  <joint name="base_to_wheel_center" type="continuous">
    <parent link="base"/>
    <child link="wheel_center"/>
    <limit effort="1" velocity="1"/>
  </joint>
  <joint name="base_laser_vert_bottom_gaze_joint" type="fixed">
    <axis xyz="0 0 1"/>
    <origin rpy="3.1354753 -1.3045001 0.0024658" xyz="0.3157894464801903 -0.002068548615034871 0.5099999434059285"/>
    <parent link="base"/>
    <child link="laser_vert_bottom_gaze"/>
  </joint>
  <link name="laser_vert_bottom_gaze">
    <collision>
      <origin rpy="0 0 0" xyz="0 0 0"/>
      <geometry>
        <box size="0.1 0.1 0.1"/>
      </geometry>
    </collision>
    <visual>
      <origin rpy="0 0 0" xyz="0 0 0"/>
      <geometry>
        <mesh filename="package://gazebo_plugins/test/multi_robot_scenario/meshes/laser/hokuyo.dae"/>
      </geometry>
    </visual>
    <inertial>
      <mass value="1e-5"/>
      <origin rpy="0 0 0" xyz="0 0 0"/>
      <inertia ixx="1e-6" ixy="0" ixz="0" iyy="1e-6" iyz="0" izz="1e-6"/>
    </inertial>
  </link>
  <gazebo reference="laser_vert_bottom_gaze">
    <sensor name="laser" type="ray">
      <pose>0 0 0 0 0 0</pose>
      <ray>
        <scan>
          <horizontal>
            <!-- The URG-04LX-UG01  has  683 steps with 0.35139 Degree resolution -->
            <resolution>1</resolution>
            <max_angle>2.0944</max_angle>
            <!-- 120 Degree -->
            <min_angle>-2.0944</min_angle>
            <!-- -120 Degree -->
            <samples>683</samples>
          </horizontal>
        </scan>
        <range>
          <min>0.08</min>
          <max>5</max>
          <resolution>0.01</resolution>
        </range>
      </ray>
      <plugin filename="libgazebo_ros_laser.so" name="laser">
        <robotNamespace/>
        <topicName>laser_vert_bottom_gaze/scan</topicName>
        <frameName>laser_vert_bottom_gaze</frameName>
      </plugin>
      <!--
          <plugin name="laser" filename="libRayPlugin.so" />
          -->
      <always_on>1</always_on>
      <update_rate>30</update_rate>
      <visualize>true</visualize>
    </sensor>
  </gazebo>
  <joint name="base_laser_vert_top_right_gaze_joint" type="fixed">
    <axis xyz="0 0 1"/>
    <origin rpy="3.1354753 -1.3045001 0.0024658" xyz="0.3157894464801903 -0.002068548615034871 0.5099999434059285"/>
    <parent link="base"/>
    <child link="laser_vert_top_right_gaze"/>
  </joint>
  <link name="laser_vert_top_right_gaze">
    <collision>
      <origin rpy="0 0 0" xyz="0 0 0"/>
      <geometry>
        <box size="0.1 0.1 0.1"/>
      </geometry>
    </collision>
    <visual>
      <origin rpy="0 0 0" xyz="0 0 0"/>
      <geometry>
        <mesh filename="package://gazebo_plugins/test/multi_robot_scenario/meshes/laser/hokuyo.dae"/>
      </geometry>
    </visual>
    <inertial>
      <mass value="1e-5"/>
      <origin rpy="0 0 0" xyz="0 0 0"/>
      <inertia ixx="1e-6" ixy="0" ixz="0" iyy="1e-6" iyz="0" izz="1e-6"/>
    </inertial>
  </link>
  <gazebo reference="laser_vert_top_right_gaze">
    <sensor name="laser" type="ray">
      <pose>0 0 0 0 0 0</pose>
      <ray>
        <scan>
          <horizontal>
            <!-- The URG-04LX-UG01  has  683 steps with 0.35139 Degree resolution -->
            <resolution>1</resolution>
            <max_angle>2.0944</max_angle>
            <!-- 120 Degree -->
            <min_angle>-2.0944</min_angle>
            <!-- -120 Degree -->
            <samples>683</samples>
          </horizontal>
        </scan>
        <range>
          <min>0.08</min>
          <max>5</max>
          <resolution>0.01</resolution>
        </range>
      </ray>
      <plugin filename="libgazebo_ros_laser.so" name="laser">
        <robotNamespace/>
        <topicName>laser_vert_top_right_gaze/scan</topicName>
        <frameName>laser_vert_top_right_gaze</frameName>
      </plugin>
      <!--
          <plugin name="laser" filename="libRayPlugin.so" />
          -->
      <always_on>1</always_on>
      <update_rate>30</update_rate>
      <visualize>true</visualize>
    </sensor>
  </gazebo>
  <joint name="base_laser_vert_top_left_gaze_joint" type="fixed">
    <axis xyz="0 0 1"/>
    <origin rpy="3.1354753 -1.3045001 0.0024658" xyz="0.3157894464801903 -0.002068548615034871 0.5099999434059285"/>
    <parent link="base"/>
    <child link="laser_vert_top_left_gaze"/>
  </joint>
  <link name="laser_vert_top_left_gaze">
    <collision>
      <origin rpy="0 0 0" xyz="0 0 0"/>
      <geometry>
        <box size="0.1 0.1 0.1"/>
      </geometry>
    </collision>
    <visual>
      <origin rpy="0 0 0" xyz="0 0 0"/>
      <geometry>
        <mesh filename="package://gazebo_plugins/test/multi_robot_scenario/meshes/laser/hokuyo.dae"/>
      </geometry>
    </visual>
    <inertial>
      <mass value="1e-5"/>
      <origin rpy="0 0 0" xyz="0 0 0"/>
      <inertia ixx="1e-6" ixy="0" ixz="0" iyy="1e-6" iyz="0" izz="1e-6"/>
    </inertial>
  </link>
  <gazebo reference="laser_vert_top_left_gaze">
    <sensor name="laser" type="ray">
      <pose>0 0 0 0 0 0</pose>
      <ray>
        <scan>
          <horizontal>
            <!-- The URG-04LX-UG01  has  683 steps with 0.35139 Degree resolution -->
            <resolution>1</resolution>
            <max_angle>2.0944</max_angle>
            <!-- 120 Degree -->
            <min_angle>-2.0944</min_angle>
            <!-- -120 Degree -->
            <samples>683</samples>
          </horizontal>
        </scan>
        <range>
          <min>0.08</min>
          <max>5</max>
          <resolution>0.01</resolution>
        </range>
      </ray>
      <plugin filename="libgazebo_ros_laser.so" name="laser">
        <robotNamespace/>
        <topicName>laser_vert_top_left_gaze/scan</topicName>
        <frameName>laser_vert_top_left_gaze</frameName>
      </plugin>
      <!--
          <plugin name="laser" filename="libRayPlugin.so" />
          -->
      <always_on>1</always_on>
      <update_rate>30</update_rate>
      <visualize>true</visualize>
    </sensor>
  </gazebo>
  <joint name="laser_horiz_velodyne_base_mount_joint" type="fixed">
    <origin rpy="-0.0012068 0.114646 -0.0015308" xyz="0.2325416305773505 -0.0001380069427607134 1.920122926231907"/>
    <parent link="base"/>
    <child link="laser_horiz_velodyne_base_link"/>
  </joint>
  <link name="laser_horiz_velodyne_base_link">
    <inertial>
      <mass value="0.83"/>
      <origin xyz="0 0 0.03585"/>
      <inertia ixx="0.000908059425" ixy="0" ixz="0" iyy="0.000908059425" iyz="0" izz="0.0011049624"/>
    </inertial>
    <visual>
      <geometry>
        <mesh filename="package://velodyne_description/meshes/VLP16_base_1.dae"/>
      </geometry>
    </visual>
    <visual>
      <geometry>
        <mesh filename="package://velodyne_description/meshes/VLP16_base_2.dae"/>
      </geometry>
    </visual>
    <collision>
      <origin rpy="0 0 0" xyz="0 0 0.03585"/>
      <geometry>
        <cylinder length="0.0717" radius="0.0516"/>
      </geometry>
    </collision>
  </link>
  <joint name="laser_horiz_velodyne_base_scan_joint" type="fixed">
    <origin rpy="0 0 0" xyz="0 0 0.0377"/>
    <parent link="laser_horiz_velodyne_base_link"/>
    <child link="laser_horiz_velodyne"/>
  </joint>
  <link name="laser_horiz_velodyne">
    <inertial>
      <mass value="0.01"/>
      <origin xyz="0 0 0"/>
      <inertia ixx="1e-7" ixy="0" ixz="0" iyy="1e-7" iyz="0" izz="1e-7"/>
    </inertial>
    <visual>
      <origin xyz="0 0 -0.0377"/>
      <geometry>
        <mesh filename="package://velodyne_description/meshes/VLP16_scan.dae"/>
      </geometry>
    </visual>
  </link>
  <!-- Gazebo requires the velodyne_gazebo_plugins package -->
  <gazebo reference="laser_horiz_velodyne">
    <sensor name="laser_horiz_velodyne-VLP16" type="ray">
      <pose>0 0 0 0 0 0</pose>
      <visualize>false</visualize>
      <update_rate>10</update_rate>
      <ray>
        <scan>
          <horizontal>
            <samples>440</samples>
            <resolution>1</resolution>
            <min_angle>-3.14159265359</min_angle>
            <max_angle>3.14159265359</max_angle>
          </horizontal>
          <vertical>
            <samples>16</samples>
            <resolution>1</resolution>
            <min_angle>-0.261799387799</min_angle>
            <max_angle> 0.261799387799</max_angle>
          </vertical>
        </scan>
        <range>
          <min>0.3</min>
          <max>131.0</max>
          <resolution>0.001</resolution>
        </range>
        <noise>
          <type>gaussian</type>
          <mean>0.0</mean>
          <stddev>0.0</stddev>
        </noise>
      </ray>
      <plugin filename="libgazebo_ros_velodyne_laser.so" name="gazebo_ros_laser_controller">
        <topicName>laser_horiz/packets</topicName>
        <frameName>laser_horiz_velodyne</frameName>
        <min_range>0.9</min_range>
        <max_range>130.0</max_range>
        <gaussianNoise>0.008</gaussianNoise>
      </plugin>
    </sensor>
  </gazebo>
</robot>

